Traceback (most recent call last):
  File "C:\Users\mcast\miniconda3\Lib\site-packages\jupyter_cache\executors\utils.py", line 58, in single_nb_execution
    executenb(
  File "C:\Users\mcast\miniconda3\Lib\site-packages\nbclient\client.py", line 1314, in execute
    return NotebookClient(nb=nb, resources=resources, km=km, **kwargs).execute()
           ^^^^^^^^^^^^^^^^^^^^^^^^^^^^^^^^^^^^^^^^^^^^^^^^^^^^^^^^^^^^^^^^^^^^^
  File "C:\Users\mcast\AppData\Roaming\Python\Python311\site-packages\jupyter_core\utils\__init__.py", line 166, in wrapped
    return loop.run_until_complete(inner)
           ^^^^^^^^^^^^^^^^^^^^^^^^^^^^^^
  File "C:\Users\mcast\miniconda3\Lib\asyncio\base_events.py", line 653, in run_until_complete
    return future.result()
           ^^^^^^^^^^^^^^^
  File "C:\Users\mcast\miniconda3\Lib\site-packages\nbclient\client.py", line 709, in async_execute
    await self.async_execute_cell(
  File "C:\Users\mcast\miniconda3\Lib\site-packages\nbclient\client.py", line 1062, in async_execute_cell
    await self._check_raise_for_error(cell, cell_index, exec_reply)
  File "C:\Users\mcast\miniconda3\Lib\site-packages\nbclient\client.py", line 918, in _check_raise_for_error
    raise CellExecutionError.from_cell_and_msg(cell, exec_reply_content)
nbclient.exceptions.CellExecutionError: An error occurred while executing the following cell:
------------------
√≠ndentity = pd.read_csv("C:\Users\mcast\OneDrive\Escritorio\ParcialML\train_identity.csv")
transaction = pd.read_csv("C:\Users\mcast\OneDrive\Escritorio\ParcialML\train_transaction.csv")
print(f"Indentity Shape: {√≠ndentity.shape}")
display(√≠ndentity.head())
print("==" * 20)
print(f"transaction Shape: {transaction.shape}")
display(transaction.head())


mapeo_fraude = {0: 'No es fraude', 1: 'Es fraude'}

transaction['isFraud'] = transaction['isFraud'].map(mapeo_fraude)

print("")
print("Proporci√≥n de cr√©ditos Fraudulentos")

sns.countplot(x='isFraud', data=transaction)
plt.title('Conteo de Creditos Fraudulentos:')
plt.show()
------------------


[1;36m  Cell [1;32mIn[2], line 1[1;36m[0m
[1;33m    √≠ndentity = pd.read_csv("C:\Users\mcast\OneDrive\Escritorio\ParcialML\train_identity.csv")[0m
[1;37m                                                                                             ^[0m
[1;31mSyntaxError[0m[1;31m:[0m (unicode error) 'unicodeescape' codec can't decode bytes in position 2-3: truncated \UXXXXXXXX escape


